Traceback (most recent call last):
  File "/home/runner/micromamba/envs/DEVELOP/lib/python3.11/site-packages/jupyter_cache/executors/utils.py", line 58, in single_nb_execution
    executenb(
  File "/home/runner/micromamba/envs/DEVELOP/lib/python3.11/site-packages/nbclient/client.py", line 1305, in execute
    return NotebookClient(nb=nb, resources=resources, km=km, **kwargs).execute()
           ^^^^^^^^^^^^^^^^^^^^^^^^^^^^^^^^^^^^^^^^^^^^^^^^^^^^^^^^^^^^^^^^^^^^^
  File "/home/runner/micromamba/envs/DEVELOP/lib/python3.11/site-packages/jupyter_core/utils/__init__.py", line 166, in wrapped
    return loop.run_until_complete(inner)
           ^^^^^^^^^^^^^^^^^^^^^^^^^^^^^^
  File "/home/runner/micromamba/envs/DEVELOP/lib/python3.11/asyncio/base_events.py", line 653, in run_until_complete
    return future.result()
           ^^^^^^^^^^^^^^^
  File "/home/runner/micromamba/envs/DEVELOP/lib/python3.11/site-packages/nbclient/client.py", line 705, in async_execute
    await self.async_execute_cell(
  File "/home/runner/micromamba/envs/DEVELOP/lib/python3.11/site-packages/nbclient/client.py", line 1058, in async_execute_cell
    await self._check_raise_for_error(cell, cell_index, exec_reply)
  File "/home/runner/micromamba/envs/DEVELOP/lib/python3.11/site-packages/nbclient/client.py", line 914, in _check_raise_for_error
    raise CellExecutionError.from_cell_and_msg(cell, exec_reply_content)
nbclient.exceptions.CellExecutionError: An error occurred while executing the following cell:
------------------
s = sd.OceInterp(ds, "SALT", longitude, latitude, depth, time)
------------------


[0;31m---------------------------------------------------------------------------[0m
[0;31mValueError[0m                                Traceback (most recent call last)
Cell [0;32mIn[4], line 1[0m
[0;32m----> 1[0m s [38;5;241m=[39m [43msd[49m[38;5;241;43m.[39;49m[43mOceInterp[49m[43m([49m[43mds[49m[43m,[49m[43m [49m[38;5;124;43m"[39;49m[38;5;124;43mSALT[39;49m[38;5;124;43m"[39;49m[43m,[49m[43m [49m[43mlongitude[49m[43m,[49m[43m [49m[43mlatitude[49m[43m,[49m[43m [49m[43mdepth[49m[43m,[49m[43m [49m[43mtime[49m[43m)[49m

File [0;32m~/work/seaduck/seaduck/seaduck/oceinterp.py:99[0m, in [0;36mOceInterp[0;34m(od, var_list, x, y, z, t, kernel_list, lagrangian, lagrange_kwarg, update_stops, return_in_between, return_pt_time, kernel_kwarg)[0m
[1;32m     97[0m     t [38;5;241m=[39m convert_time(t)
[1;32m     98[0m [38;5;28;01melse[39;00m:
[0;32m---> 99[0m     [38;5;28;01mraise[39;00m [38;5;167;01mValueError[39;00m([38;5;124m"[39m[38;5;124mtime format not supported[39m[38;5;124m"[39m)
[1;32m    100[0m [38;5;28;01mif[39;00m [38;5;129;01mnot[39;00m lagrangian:
[1;32m    101[0m     pt [38;5;241m=[39m Position()

[0;31mValueError[0m: time format not supported

